Workbook
Name Coeffs_133: Coefficients!$Y$28
Name Coeffs_221: Coefficients!$C$61
Name TypeSelect: Coefficients!$AJ$23
Name Coeffs_141: Coefficients!$C$39
Name Coeffs_123: Coefficients!$Y$17
Name Coeffs_121: Coefficients!$C$17
Name FamSelect: Coefficients!$AJ$8
Name Coeffs_113: Coefficients!$Y$6
Name UN: Coefficients!$AI$17:$AI$21
Name Coeffs_251: Coefficients!$C$94
Name Coeffs_143: Coefficients!$Y$39
Name Coeffs_111: Coefficients!$C$6
Name Princeton: Coefficients!$AI$13:$AI$16
Name Family: Coefficients!$AI$9:$AI$10
Name Coeffs_131: Coefficients!$C$28
Name Coeffs_241: Coefficients!$C$83
Name Variant: Coefficients!$AI$24:$AI$26
Name Coeffs_231: Coefficients!$C$72
Name Coeffs_132: Coefficients!$N$28
Name Coeffs_112: Coefficients!$N$6
Name Coeffs_211: Coefficients!$C$50
Name Coeffs_142: Coefficients!$N$39
Name Sex: Coefficients!$AI$29:$AI$31
Name Coeffs_122: Coefficients!$N$17

Sheet Introduction
A1: Estimation of child mortality using data on children ever born and children surviving - Instructions
A3: This method is described at:
A4: http://demographicestimation.iussp.org/content/indirect-estimation-child-mortality
A6: This spreadsheet estimates child mortality from data on the mean number of children ever born and surviving by age of mother, the duration since first birth, or duration since marriage.
A8: Set input parameters
A9: 1 | B9: Enter the country name and data descriptor in the green cell to the right. | C9: Country | D9: México
A11: 2 | B11: Record the date of the inquiry in the green cell to the right. | C11: Census date | D11: 43891
A14: 3 | B14: Specify the variant of the model to be fitted. | C14: Variant of method | D14: Age of mother
A17: 4 | B17: Set the mortality parameters for the method in the green cells to the right. | C17: Family of model life tables | D17: Princeton
C18: Mortality pattern | D18: West
C20: Sex | D20: Both
C21: Mean age of childbearing | D21: 28
A23: 5 | B23: Place the mean number of children ever born, tabulated according to the variant of the model in cells B5:B11 of the Method sheet. | C23: =IF(ISNA(VLOOKUP(VALUE(RIGHT(Coefficients!AM5,3)),Coefficients!$AI$34:$AI$50,1,FALSE)),"INVALID SELECTION - Please ensure that your choice of variant; family and pattern are consistent.","")
A25: 6 | B25: Place the mean number of children surviving, tabulated according to the variant of the model in cells C5:C11 of the Method sheet.
A27: Results
B28: Estimates of infant mortality, q(1), and child mortality, q(5), are located in cells L5:M10 of the Method sheet.
B29: Time locations of these estimates are located in cells K5:K10 of the Method sheet.

Sheet Coefficients
A1: BY AGE OF MOTHER | L1: BY DURATION SINCE FIRST BIRTH | W1: BY DURATION SINCE MARRIAGE
C3: Conversion of D into q | H3: Time location | N3: Conversion of D into q | S3: Time location | Y3: Conversion of D into q | AD3: Time location
A4: Princeton - North | N4: Princeton - North | Y4: Princeton - North
A5: Age | B5: x | C5: a(x,j) | D5: b(x,j) | E5: c(x,j) | F5: d(x,j) | H5: e(x,j) | I5: f(x,j) | J5: g(x,j) | L5: Duration | M5: x | N5: a(x,j) | O5: b(x,j) | P5: c(x,j) | S5: e(x,j) | T5: f(x,j) | U5: g(x,j) | W5: Duration | X5: x | Y5: a(x,j) | Z5: b(x,j) | AA5: c(x,j) | AD5: e(x,j) | AE5: f(x,j) | AF5: g(x,j) | AH5: =Introduction!D9&" "&TEXT(YEAR(Introduction!D11),"####") -> México 2020 | AM5: ="Coeffs_"&TEXT(100*AJ8+10*AJ12+AJ23,0) -> Coeffs_141
A6: 15-19 | B6: 1 | C6: 1.1119 | D6: -2.9287 | E6: 0.8507 | H6: 1.0921 | I6: 5.4732 | J6: -1.9672 | L6: 0-4 | M6: 2 | N6: 1.198 | O6: -0.1266 | P6: 0.0038 | S6: 1.71 | T6: 1.07 | U6: -0.35 | W6: 0-4 | X6: 2 | Y6: 1.2615 | Z6: -0.534 | AA6: 0.1252 | AD6: 1.0311 | AE6: 1.3149 | AF6: -0.3282 | AH6: Census date | AJ6: =YEAR(Introduction!D11)+YEARFRAC(DATE(YEAR(Introduction!D11)-1,12,31), Introduction!D11,1) -> 2020.1667 | AM6: 0 | AN6: 1 | AO6: 2 | AP6: 3 | AR6: 5 | AS6: 6 | AT6: 7 | AV6: Metric
A7: 20-24 | B7: 2 | C7: 1.239 | D7: -0.6865 | E7: -0.2745 | H7: 1.3207 | I7: 5.3751 | J7: 0.2133 | L7: 5-9 | M7: 5 | N7: 1.2248 | O7: -0.1919 | P7: -0.087 | S7: 2.16 | T7: 4.36 | U7: 0.12 | W7: 5-9 | X7: 3 | Y7: 1.1957 | Z7: -0.4103 | AA7: -0.093 | AD7: 1.6964 | AE7: 4.5147 | AF7: -0.016 | AL7: 0 | AM7: =OFFSET(INDIRECT($AM$5),$AL7,AM$6) -> 1.1415 | AN7: =OFFSET(INDIRECT($AM$5),$AL7,AN$6) -> -2.707 | AO7: =OFFSET(INDIRECT($AM$5),$AL7,AO$6) -> 0.7663 | AP7: =OFFSET(INDIRECT($AM$5),$AL7,AP$6) | AR7: =OFFSET(INDIRECT($AM$5),$AL7,AR$6) -> 1.097 | AS7: =OFFSET(INDIRECT($AM$5),$AL7,AS$6) -> 5.5628 | AT7: =OFFSET(INDIRECT($AM$5),$AL7,AT$6) -> -1.9956 | AV7: =OFFSET(INDIRECT($AM$5),AL7,-1) -> 1
A8: 25-29 | B8: 3 | C8: 1.1884 | D8: 0.0421 | E8: -0.5156 | H8: 1.5996 | I8: 2.6268 | J8: 4.3701 | L8: 10-14 | M8: 5 | N8: 1.2076 | O8: -0.0105 | P8: -0.2911 | S8: 0.66 | T8: 3.5 | U8: 6.65 | W8: 10-14 | X8: 5 | Y8: 1.3067 | Z8: -0.0103 | AA8: -0.4618 | AD8: 1.4285 | AE8: 3.2684 | AF8: 4.4073 | AH8: Model family | AJ8: =MATCH(Introduction!D17,Family,0) -> 1 | AL8: 1 | AM8: =OFFSET(INDIRECT($AM$5),$AL8,AM$6) -> 1.2563 | AN8: =OFFSET(INDIRECT($AM$5),$AL8,AN$6) -> -0.5381 | AO8: =OFFSET(INDIRECT($AM$5),$AL8,AO$6) -> -0.2637 | AP8: =OFFSET(INDIRECT($AM$5),$AL8,AP$6) | AR8: =OFFSET(INDIRECT($AM$5),$AL8,AR$6) -> 1.3062 | AS8: =OFFSET(INDIRECT($AM$5),$AL8,AS$6) -> 5.5677 | AT8: =OFFSET(INDIRECT($AM$5),$AL8,AT$6) -> 0.2962 | AV8: =OFFSET(INDIRECT($AM$5),AL8,-1) -> 2
A9: 30-34 | B9: 5 | C9: 1.2046 | D9: 0.3037 | E9: -0.5656 | H9: 2.0779 | I9: -1.7908 | J9: 9.4126 | L9: 15-19 | M9: 5 | N9: 1.203 | O9: 0.0896 | P9: -0.4265 | S9: -1.96 | T9: -0.9 | U9: 17.66 | W9: 15-19 | X9: 10 | Y9: 1.4701 | Z9: 0.1763 | AA9: -0.7268 | AD9: -0.0753 | AE9: -1.08 | AF9: 12.9281 | AI9: Princeton | AL9: 2 | AM9: =OFFSET(INDIRECT($AM$5),$AL9,AM$6) -> 1.1851 | AN9: =OFFSET(INDIRECT($AM$5),$AL9,AN$6) -> 0.0633 | AO9: =OFFSET(INDIRECT($AM$5),$AL9,AO$6) -> -0.4177 | AP9: =OFFSET(INDIRECT($AM$5),$AL9,AP$6) | AR9: =OFFSET(INDIRECT($AM$5),$AL9,AR$6) -> 1.5305 | AS9: =OFFSET(INDIRECT($AM$5),$AL9,AS$6) -> 2.5528 | AT9: =OFFSET(INDIRECT($AM$5),$AL9,AT$6) -> 4.8962 | AV9: =OFFSET(INDIRECT($AM$5),AL9,-1) -> 3
A10: 35-39 | B10: 10 | C10: 1.2586 | D10: 0.4236 | E10: -0.5898 | H10: 2.7705 | I10: -7.3403 | J10: 14.9352 | L10: 20-24 | M10: 10 | N10: 1.3292 | O10: 0.1598 | P10: -0.5778 | S10: -3.85 | T10: -6.42 | U10: 28.94 | W10: 20-24 | X10: 15 | Y10: 1.5039 | Z10: 0.0039 | AA10: -0.7071 | AD10: -1.9749 | AE10: -3.4773 | AF10: 21.3318 | AI10: UN | AL10: 3 | AM10: =OFFSET(INDIRECT($AM$5),$AL10,AM$6) -> 1.172 | AN10: =OFFSET(INDIRECT($AM$5),$AL10,AN$6) -> 0.2341 | AO10: =OFFSET(INDIRECT($AM$5),$AL10,AO$6) -> -0.4272 | AP10: =OFFSET(INDIRECT($AM$5),$AL10,AP$6) | AR10: =OFFSET(INDIRECT($AM$5),$AL10,AR$6) -> 1.9991 | AS10: =OFFSET(INDIRECT($AM$5),$AL10,AS$6) -> -2.4261 | AT10: =OFFSET(INDIRECT($AM$5),$AL10,AT$6) -> 10.4282 | AV10: =OFFSET(INDIRECT($AM$5),AL10,-1) -> 5
A11: 40-44 | B11: 15 | C11: 1.224 | D11: 0.4222 | E11: -0.5456 | H11: 4.152 | I11: -12.2448 | J11: 19.2349 | W11: 25-29 | X11: 20 | Y11: 1.4798 | Z11: -0.2487 | AA11: -0.5582 | AD11: -2.1888 | AE11: 0.6124 | AF11: 23.9376 | AL11: 4 | AM11: =OFFSET(INDIRECT($AM$5),$AL11,AM$6) -> 1.1865 | AN11: =OFFSET(INDIRECT($AM$5),$AL11,AN$6) -> 0.308 | AO11: =OFFSET(INDIRECT($AM$5),$AL11,AO$6) -> -0.4452 | AP11: =OFFSET(INDIRECT($AM$5),$AL11,AP$6) | AR11: =OFFSET(INDIRECT($AM$5),$AL11,AR$6) -> 2.7632 | AS11: =OFFSET(INDIRECT($AM$5),$AL11,AS$6) -> -8.4065 | AT11: =OFFSET(INDIRECT($AM$5),$AL11,AT$6) -> 16.1787 | AV11: =OFFSET(INDIRECT($AM$5),AL11,-1) -> 10
A12: 45-49 | B12: 20 | C12: 1.1772 | D12: 0.3486 | E12: -0.4624 | H12: 6.965 | I12: -13.916 | J12: 19.9542 | AH12: Model pattern | AJ12: =MATCH(Introduction!D18,IF(AJ8=1,Princeton,UN),0) -> 4 | AL12: 5 | AM12: =OFFSET(INDIRECT($AM$5),$AL12,AM$6) -> 1.1746 | AN12: =OFFSET(INDIRECT($AM$5),$AL12,AN$6) -> 0.3314 | AO12: =OFFSET(INDIRECT($AM$5),$AL12,AO$6) -> -0.4537 | AP12: =OFFSET(INDIRECT($AM$5),$AL12,AP$6) | AR12: =OFFSET(INDIRECT($AM$5),$AL12,AR$6) -> 4.3468 | AS12: =OFFSET(INDIRECT($AM$5),$AL12,AS$6) -> -13.2436 | AT12: =OFFSET(INDIRECT($AM$5),$AL12,AT$6) -> 20.199 | AV12: =OFFSET(INDIRECT($AM$5),AL12,-1) -> 15
AI13: North | AL13: 6 | AM13: =OFFSET(INDIRECT($AM$5),$AL13,AM$6) -> 1.1639 | AN13: =OFFSET(INDIRECT($AM$5),$AL13,AN$6) -> 0.319 | AO13: =OFFSET(INDIRECT($AM$5),$AL13,AO$6) -> -0.4435 | AP13: =OFFSET(INDIRECT($AM$5),$AL13,AP$6) | AR13: =OFFSET(INDIRECT($AM$5),$AL13,AR$6) -> 7.5242 | AS13: =OFFSET(INDIRECT($AM$5),$AL13,AS$6) -> -14.2013 | AT13: =OFFSET(INDIRECT($AM$5),$AL13,AT$6) -> 20.0162 | AV13: =OFFSET(INDIRECT($AM$5),AL13,-1) -> 20
AI14: South
A15: Princeton - South | N15: Princeton - South | Y15: Princeton - South | AI15: East | AM15: Selected LT
A16: Age | B16: x | C16: a(x,j) | D16: b(x,j) | E16: c(x,j) | F16: d(x,j) | H16: e(x,j) | I16: f(x,j) | J16: g(x,j) | L16: Duration | M16: x | N16: a(x,j) | O16: b(x,j) | P16: c(x,j) | S16: e(x,j) | T16: f(x,j) | U16: g(x,j) | W16: Duration | X16: x | Y16: a(x,j) | Z16: b(x,j) | AA16: c(x,j) | AD16: e(x,j) | AE16: f(x,j) | AF16: g(x,j) | AI16: West | AM16: x | AN16: logit l(x)
A17: 15-19 | B17: 1 | C17: 1.0819 | D17: -3.0005 | E17: 0.8689 | H17: 1.09 | I17: 5.4443 | J17: -1.9721 | L17: 0-4 | M17: 2 | N17: 1.1705 | O17: -0.1461 | P17: 0.0051 | S17: 1.68 | T17: 0.96 | U17: -0.32 | W17: 0-4 | X17: 2 | Y17: 1.3103 | Z17: -0.5856 | AA17: 0.1367 | AD17: 1.0202 | AE17: 1.3064 | AF17: -0.3297 | AI17: Latin America | AM17: 0
A18: 20-24 | B18: 2 | C18: 1.2846 | D18: -0.6181 | E18: -0.3024 | H18: 1.3079 | I18: 5.5568 | J18: 0.2021 | L18: 5-9 | M18: 5 | N18: 1.3166 | O18: -0.3157 | P18: -0.0971 | S18: 2.29 | T18: 3.84 | U18: -0.01 | W18: 5-9 | X18: 3 | Y18: 1.2309 | Z18: -0.3463 | AA18: -0.1073 | AD18: 1.6601 | AE18: 4.5105 | AF18: -0.0335 | AI18: Chile | AM18: 1 | AN18: =HLOOKUP(Coefficients!$AJ$8*100+Coefficients!$AJ$12*10+Coefficients!$AJ$28,'Model LTs'!$A$2:$AB$13,5,FALSE) -> -1.2920085
A19: 25-29 | B19: 3 | C19: 1.2223 | D19: 0.0851 | E19: -0.4704 | H19: 1.5173 | I19: 2.6755 | J19: 4.7471 | L19: 10-14 | M19: 5 | N19: 1.2952 | O19: -0.0423 | P19: -0.4295 | S19: 1.19 | T19: 3.45 | U19: 5.41 | W19: 10-14 | X19: 5 | Y19: 1.2774 | Z19: 0.0336 | AA19: -0.3987 | AD19: 1.2146 | AE19: 3.4684 | AF19: 4.9524 | AI19: South Asian | AM19: 2 | AN19: =HLOOKUP(Coefficients!$AJ$8*100+Coefficients!$AJ$12*10+Coefficients!$AJ$28,'Model LTs'!$A$2:$AB$13,6,FALSE) -> -1.199382
A20: 30-34 | B20: 5 | C20: 1.1905 | D20: 0.2631 | E20: -0.4487 | H20: 1.9399 | I20: -2.2739 | J20: 10.3876 | L20: 15-19 | M20: 5 | N20: 1.2836 | O20: 0.1308 | P20: -0.6496 | S20: -1.01 | T20: -0.18 | U20: 15.03 | W20: 15-19 | X20: 10 | Y20: 1.3493 | Z20: 0.1366 | AA20: -0.5403 | AD20: -0.6454 | AE20: -1.6045 | AF20: 14.6773 | AI20: Far East | AM20: 3 | AN20: =HLOOKUP(Coefficients!$AJ$8*100+Coefficients!$AJ$12*10+Coefficients!$AJ$28,'Model LTs'!$A$2:$AB$13,7,FALSE) -> -1.1592413
A21: 35-39 | B21: 10 | C21: 1.1911 | D21: 0.3152 | E21: -0.4291 | H21: 2.6157 | I21: -8.4819 | J21: 16.5153 | L21: 20-24 | M21: 10 | N21: 1.5269 | O21: 0.2659 | P21: -0.9174 | S21: -2.68 | T21: -5.06 | U21: 25.21 | W21: 20-24 | X21: 15 | Y21: 1.3592 | Z21: -0.0315 | AA21: -0.4944 | AD21: -2.9104 | AE21: -4.1352 | AF21: 24.0072 | AI21: General | AM21: 4 | AN21: =HLOOKUP(Coefficients!$AJ$8*100+Coefficients!$AJ$12*10+Coefficients!$AJ$28,'Model LTs'!$A$2:$AB$13,8,FALSE) -> -1.1338485
A22: 40-44 | B22: 15 | C22: 1.1564 | D22: 0.3017 | E22: -0.3958 | H22: 4.0794 | I22: -13.8308 | J22: 21.1866 | W22: 25-29 | X22: 20 | Y22: 1.3532 | Z22: -0.1978 | AA22: -0.4099 | AD22: -3.1641 | AE22: 1.2106 | AF22: 26.3515 | AM22: 5 | AN22: =HLOOKUP(Coefficients!$AJ$8*100+Coefficients!$AJ$12*10+Coefficients!$AJ$28,'Model LTs'!$A$2:$AB$13,9,FALSE) -> -1.1143193
A23: 45-49 | B23: 20 | C23: 1.1307 | D23: 0.2596 | E23: -0.3538 | H23: 7.1796 | I23: -15.388 | J23: 21.7892 | AH23: Model variant | AJ23: =MATCH(Introduction!D14,Variant,0) -> 1 | AM23: 10 | AN23: =HLOOKUP(Coefficients!$AJ$8*100+Coefficients!$AJ$12*10+Coefficients!$AJ$28,'Model LTs'!$A$2:$AB$13,10,FALSE) -> -1.064845
AI24: Age of mother | AM24: 15 | AN24: =HLOOKUP(Coefficients!$AJ$8*100+Coefficients!$AJ$12*10+Coefficients!$AJ$28,'Model LTs'!$A$2:$AB$13,11,FALSE) -> -1.029312
AI25: Duration since first birth | AM25: 20 | AN25: =HLOOKUP(Coefficients!$AJ$8*100+Coefficients!$AJ$12*10+Coefficients!$AJ$28,'Model LTs'!$A$2:$AB$13,12,FALSE) -> -0.97893414
A26: Princeton - East | N26: Princeton - East | Y26: Princeton - East | AI26: Duration since marriage
A27: Age | B27: x | C27: a(x,j) | D27: b(x,j) | E27: c(x,j) | F27: d(x,j) | H27: e(x,j) | I27: f(x,j) | J27: g(x,j) | L27: Duration | M27: x | N27: a(x,j) | O27: b(x,j) | P27: c(x,j) | S27: e(x,j) | T27: f(x,j) | U27: g(x,j) | W27: Duration | X27: x | Y27: a(x,j) | Z27: b(x,j) | AA27: c(x,j) | AD27: e(x,j) | AE27: f(x,j) | AF27: g(x,j)
A28: 15-19 | B28: 1 | C28: 1.1461 | D28: -2.2536 | E28: 0.6259 | H28: 1.0959 | I28: 5.5864 | J28: -1.9949 | L28: 0-4 | M28: 2 | N28: 1.2182 | O28: -0.1809 | P28: 0.0214 | S28: 1.68 | T28: 0.99 | U28: -0.33 | W28: 0-4 | X28: 2 | Y28: 1.2299 | Z28: -0.3998 | AA28: 0.091 | AD28: 1.038 | AE28: 1.4213 | AF28: -0.3545 | AH28: Sex | AJ28: =MATCH(Introduction!D20,Sex,0) -> 3
A29: 20-24 | B29: 2 | C29: 1.2231 | D29: -0.4301 | E29: -0.2245 | H29: 1.2921 | I29: 5.5897 | J29: 0.3631 | L29: 5-9 | M29: 5 | N29: 1.2769 | O29: -0.2268 | P29: -0.1052 | S29: 2.19 | T29: 4.28 | U29: 0.02 | W29: 5-9 | X29: 3 | Y29: 1.1611 | Z29: -0.2451 | AA29: -0.0797 | AD29: 1.6441 | AE29: 4.7042 | AF29: 0.0642 | AI29: Male
A30: 25-29 | B30: 3 | C30: 1.1593 | D30: 0.0581 | E30: -0.3479 | H30: 1.5021 | I30: 2.4692 | J30: 5.0927 | L30: 10-14 | M30: 5 | N30: 1.2731 | O30: 0.0005 | P30: -0.372 | S30: 0.71 | T30: 3.63 | U30: 6.36 | W30: 10-14 | X30: 5 | Y30: 1.2036 | Z30: 0.0171 | AA30: -0.2992 | AD30: 1.1068 | AE30: 3.3032 | AF30: 5.4464 | AI30: Female
A31: 30-34 | B31: 5 | C31: 1.1404 | D31: 0.1991 | E31: -0.3487 | H31: 1.9347 | I31: -2.6419 | J31: 10.8533 | L31: 15-19 | M31: 5 | N31: 1.2585 | O31: 0.1216 | P31: -0.5013 | S31: -1.96 | T31: -0.71 | U31: 17.42 | W31: 15-19 | X31: 10 | Y31: 1.2773 | Z31: 0.1015 | AA31: -0.4276 | AD31: -0.8678 | AE31: -1.9683 | AF31: 15.5187 | AI31: Both
A32: 35-39 | B32: 10 | C32: 1.154 | D32: 0.2511 | E32: -0.3506 | H32: 2.6197 | I32: -8.9693 | J32: 17.0981 | L32: 20-24 | M32: 10 | N32: 1.341 | O32: 0.1749 | P32: -0.5964 | S32: -4.06 | T32: -6.35 | U32: 29.14 | W32: 20-24 | X32: 15 | Y32: 1.3014 | Z32: -0.0219 | AA32: -0.4195 | AD32: -3.2154 | AE32: -4.1123 | AF32: 24.8624
A33: 40-44 | B33: 15 | C33: 1.1336 | D33: 0.2556 | E33: -0.3428 | H33: 4.1317 | I33: -14.355 | J33: 21.8247 | W33: 25-29 | X33: 20 | Y33: 1.316 | Z33: -0.163 | AA33: -0.3751 | AD33: -3.3885 | AE33: 1.6746 | AF33: 26.9798 | AH33: Valid combinations | AJ33: =VLOOKUP(100*AJ8+10*AJ12+AJ23,$AI$34:$AI$50,1,FALSE) -> 141
A34: 45-49 | B34: 20 | C34: 1.1201 | D34: 0.2362 | E34: -0.3268 | H34: 7.3657 | I34: -15.8083 | J34: 22.3005 | AI34: 111
AI35: 121
AI36: 131
A37: Princeton - West | N37: Princeton - West | Y37: Princeton - West | AI37: 141
A38: Age | B38: x | C38: a(x,j) | D38: b(x,j) | E38: c(x,j) | F38: d(x,j) | H38: e(x,j) | I38: f(x,j) | J38: g(x,j) | L38: Duration | M38: x | N38: a(x,j) | O38: b(x,j) | P38: c(x,j) | S38: e(x,j) | T38: f(x,j) | U38: g(x,j) | W38: Duration | X38: x | Y38: a(x,j) | Z38: b(x,j) | AA38: c(x,j) | AD38: e(x,j) | AE38: f(x,j) | AF38: g(x,j) | AI38: 211
A39: 15-19 | B39: 1 | C39: 1.1415 | D39: -2.707 | E39: 0.7663 | H39: 1.097 | I39: 5.5628 | J39: -1.9956 | L39: 0-4 | M39: 2 | N39: 1.2049 | O39: -0.1553 | P39: 0.0135 | S39: 1.7 | T39: 1.03 | U39: -0.34 | W39: 0-4 | X39: 2 | Y39: 1.2584 | Z39: -0.4683 | AA39: 0.108 | AD39: 1.0349 | AE39: 1.3714 | AF39: -0.339 | AI39: 221
A40: 20-24 | B40: 2 | C40: 1.2563 | D40: -0.5381 | E40: -0.2637 | H40: 1.3062 | I40: 5.5677 | J40: 0.2962 | L40: 5-9 | M40: 5 | N40: 1.2573 | O40: -0.2266 | P40: -0.0944 | S40: 2.2 | T40: 4.2 | U40: 0.06 | W40: 5-9 | X40: 3 | Y40: 1.1841 | Z40: -0.3006 | AA40: -0.0892 | AD40: 1.6654 | AE40: 4.4588 | AF40: 0.0233 | AI40: 231
A41: 25-29 | B41: 3 | C41: 1.1851 | D41: 0.0633 | E41: -0.4177 | H41: 1.5305 | I41: 2.5528 | J41: 4.8962 | L41: 10-14 | M41: 5 | N41: 1.2431 | O41: -0.023 | P41: -0.3409 | S41: 0.86 | T41: 3.47 | U41: 6.21 | W41: 10-14 | X41: 5 | Y41: 1.2446 | Z41: 0.0131 | AA41: -0.3555 | AD41: 1.2109 | AE41: 3.3291 | AF41: 5.1402 | AI41: 241
...

Sheet Model LTs
A1: Model LTs | B1: logits with e0 = 60
B2: 111 | C2: 112 | D2: 113 | E2: 121 | F2: 122 | G2: 123 | H2: 131 | I2: 132 | J2: 133 | K2: 141 | L2: 142 | M2: 143 | N2: 211 | O2: 212 | P2: 213 | Q2: 221 | R2: 222 | S2: 223 | T2: 231 | U2: 232 | V2: 233 | W2: 241 | X2: 242 | Y2: 243 | Z2: 251 | AA2: 252 | AB2: 253
B3: Princeton North | E3: Princeton South | H3: Princeton East | K3: Princeton West | N3: UN Latin American | Q3: UN Chilean | T3: UN South Asian | W3: UN Far Eastern | Z3: UN General
A4: x | B4: Males | C4: Females | D4: Combined | E4: Males | F4: Females | G4: Combined | H4: Males | I4: Females | J4: Combined | K4: Males | L4: Females | M4: Combined | N4: Males | O4: Females | P4: Combined | Q4: Males | R4: Females | S4: Combined | T4: Males | U4: Females | V4: Combined | W4: Males | X4: Females | Y4: Combined | Z4: Males | AA4: Females | AB4: Combined
A5: 0
A6: 1 | B6: -1.3391919 | C6: -1.3205377 | D6: -1.3300167 | E6: -1.149543 | F6: -1.1287565 | G6: -1.1393153 | H6: -1.1995667 | I6: -1.1590577 | J6: -1.1794669 | K6: -1.3008883 | L6: -1.2828283 | M6: -1.2920085 | N6: -1.2244025 | O6: -1.2375303 | P6: -1.23077 | Q6: -1.1881811 | R6: -1.1106269 | S6: -1.149121 | T6: -1.1633365 | U6: -1.1378733 | V6: -1.1507829 | W6: -1.4833929 | X6: -1.3772257 | Y6: -1.4290934 | Z6: -1.2808738 | AA6: -1.2702343 | AB6: -1.2756596
A7: 2 | B7: -1.2482714 | C7: -1.2060903 | D7: -1.2273209 | E7: -1.0529219 | F7: -1.0009991 | G7: -1.0270731 | H7: -1.1377254 | I7: -1.073353 | J7: -1.1054932 | K7: -1.2215537 | L7: -1.1769512 | M7: -1.199382 | N7: -1.1230472 | O7: -1.1005761 | P7: -1.1119841 | Q7: -1.1426713 | R7: -1.0454 | S7: -1.0933348 | T7: -1.0463869 | U7: -1.0078054 | V7: -1.0272792 | W7: -1.4168729 | X7: -1.2912754 | Y7: -1.3521595 | Z7: -1.1994286 | AA7: -1.1587987 | AB7: -1.1792678
A8: 3 | B8: -1.1910199 | C8: -1.1415199 | D8: -1.1663695 | E8: -1.0116418 | F8: -0.94932383 | G8: -0.98051169 | H8: -1.1122189 | I8: -1.0396889 | J8: -1.0757977 | K8: -1.1859677 | L8: -1.1323859 | M8: -1.1592413 | N8: -1.0763916 | O8: -1.039815 | P8: -1.0582869 | Q8: -1.1204664 | R8: -1.0161031 | S8: -1.0674115 | T8: -0.99614964 | U8: -0.95267015 | V8: -0.97458547 | W8: -1.3824459 | X8: -1.2510803 | Y8: -1.3146345 | Z8: -1.1601037 | AA8: -1.1075443 | AB8: -1.1339041
A9: 4 | B9: -1.1495156 | C9: -1.0955047 | D9: -1.1225794 | E9: -0.99004099 | F9: -0.92335584 | G9: -0.95668616 | H9: -1.0959154 | I9: -1.0182341 | J9: -1.0568391 | K9: -1.1622355 | L9: -1.1053872 | M9: -1.1338485 | N9: -1.0483131 | O9: -1.0046334 | P9: -1.0266376 | Q9: -1.1064494 | R9: -0.99875 | S9: -1.0516453 | T9: -0.9677394 | U9: -0.92208657 | V9: -0.94508558 | W9: -1.3597145 | X9: -1.2265312 | Y9: -1.2909394 | Z9: -1.1355662 | AA9: -1.0767437 | AB9: -1.1061781
A10: 5 | B10: -1.1185632 | C10: -1.0613253 | D10: -1.0899898 | E10: -0.97803105 | F10: -0.90879111 | G10: -0.94337274 | H10: -1.0839282 | I10: -1.0034528 | J10: -1.0434107 | K10: -1.1443837 | L10: -1.0842444 | M10: -1.1143193 | N10: -1.0292629 | O10: -0.98147967 | P10: -1.0055181 | Q10: -1.0965956 | R10: -0.98713579 | S10: -1.0408706 | T10: -0.94947888 | U10: -0.90273095 | V10: -0.92627697 | W10: -1.3430952 | X10: -1.2095785 | Y10: -1.2741583 | Z10: -1.1183427 | AA10: -1.0557703 | AB10: -1.0870409
A11: 10 | B11: -1.0393563 | C11: -0.97867737 | D11: -1.0090526 | E11: -0.94784308 | F11: -0.87426675 | G11: -0.91097597 | H11: -1.0472539 | I11: -0.96210277 | J11: -1.0043335 | K11: -1.0968312 | L11: -1.0329082 | M11: -1.064845 | N11: -0.98369901 | O11: -0.93040264 | P11: -0.95717334 | Q11: -1.071048 | R11: -0.96012757 | S11: -1.0145804 | T11: -0.91071239 | U11: -0.86341317 | V11: -0.88724264 | W11: -1.2967451 | X11: -1.1678086 | Y11: -1.2303496 | Z11: -1.0743949 | AA11: -1.0059691 | AB11: -1.0401061
A12: 15 | B12: -0.99810318 | C12: -0.93456379 | D12: -0.96635457 | E12: -0.92724295 | F12: -0.85272015 | G12: -0.88990311 | H12: -1.0232405 | I12: -0.93688771 | J12: -0.97971407 | K12: -1.0631132 | L12: -0.99562585 | M12: -1.029312 | N12: -0.95845256 | O12: -0.90544375 | P12: -0.93208089 | Q12: -1.0502865 | R12: -0.93957838 | S12: -0.9939579 | T12: -0.89415624 | U12: -0.84720718 | V12: -0.87086768 | W12: -1.2584277 | X12: -1.1373287 | Y12: -1.1963047 | Z12: -1.0466409 | AA12: -0.97788284 | AB12: -1.0121946
A13: 20 | B13: -0.94163339 | C13: -0.88577608 | D13: -0.91382222 | E13: -0.89806981 | F13: -0.82207222 | G13: -0.8599929 | H13: -0.98210627 | I13: -0.90144694 | J13: -0.94156372 | K13: -1.0130423 | L13: -0.94491044 | M13: -0.97893415 | N13: -0.92315127 | O13: -0.87353504 | P13: -0.89850801 | Q13: -1.015086 | R13: -0.90716031 | S13: -0.96027266 | T13: -0.87450043 | U13: -0.82539225 | V13: -0.85012871 | W13: -1.2020972 | X13: -1.0804887 | Y13: -1.1397671 | Z13: -1.0066774 | AA13: -0.93810587 | AB13: -0.97234684

Sheet Decrementos Múltiples
B2: Hombres, 2019
B3: Age x | C3: n | D3: nDx | E3: nDxi | I3: nqx | K3: e0 | M3: nqx_i | O3: ndx_i | Q3: L | R3: T | S3: e0_i | T3: diff
B4: 0 | C4: 1 | D4: ='Defunciones generales'!D21 -> 725.88054 | E4: =Homicidios!D483 -> 1.0142698 | F4: =(D4-E4)/D4 -> 0.9986027 | G4: =LT!H21 -> 100000 | H4: =1-LT!F21 -> 0.98716 | I4: =1-H4 -> 0.01284 | J4: =LT!G21 -> 0.08 | K4: =LT!L21 -> 73.46 | L4: =H4^F4 -> 0.98717783 | M4: =1-L4 -> 0.012822174 | N4: 100000 | O4: =N4*M4 -> 1282.2174 | P4: =C4+(F4*(I4/M4)*(J4-C4)) -> 0.080008289 | Q4: =(C4*N5)+(P4*O4) -> 98820.371 | R4: =R5+Q4 -> 7448886.7 | S4: =R4/N4 -> 74.488867 | T4: =S4-K4 -> 1.0288673
B5: 1 | C5: 4 | D5: ='Defunciones generales'!D22 -> 153.84322 | E5: =Homicidios!D484 -> 2.0216718 | F5: =(D5-E5)/D5 -> 0.98685888 | G5: =LT!H22 -> 98716 | H5: =1-LT!F22 -> 0.997569 | I5: =1-H5 -> 0.002431 | J5: =LT!G22 -> 1.61 | K5: =LT!L22 -> 73.42 | L5: =H5^F5 -> 0.99760091 | M5: =1-L5 -> 0.0023990923 | N5: =N4*L4 -> 98717.783 | O5: =N5*M5 -> 236.83307 | P5: =C5+(F5*(I5/M5)*(J5-C5)) -> 1.6100382 | Q5: =(C5*N6)+(P5*O5) -> 394305.11 | R5: =R6+Q5 -> 7350066.4 | S5: =R5/N5 -> 74.455343 | T5: =S5-K5 -> 1.035343 | V5: Número de años que se espera que viva un hombre de 0 años hasta llegar a los 85 años.
B6: 5 | C6: 5 | D6: ='Defunciones generales'!D23 -> 83.178484 | E6: =Homicidios!D485 -> 2.0319735 | F6: =(D6-E6)/D6 -> 0.97557092 | G6: =LT!H23 -> 98476 | H6: =1-LT!F23 -> 0.998795 | I6: =1-H6 -> 0.001205 | J6: =LT!G23 -> 2.5 | K6: =LT!L23 -> 69.59 | L6: =H6^F6 -> 0.99882442 | M6: =1-L6 -> 0.0011755803 | N6: =N5*L5 -> 98480.95 | O6: =N6*M6 -> 115.77226 | P6: =C6+(F6*(I6/M6)*(J6-C6)) -> 2.5000368 | Q6: =(C6*N7)+(P6*O6) -> 492115.32 | R6: =R7+Q6 -> 6955761.2 | S6: =R6/N6 -> 70.630526 | T6: =S6-K6 -> 1.0405259
B7: 10 | C7: 5 | D7: ='Defunciones generales'!D24 -> 106.23055 | E7: =Homicidios!D486 -> 7.0964548 | F7: =(D7-E7)/D7 -> 0.93319761 | G7: =LT!H24 -> 98357 | H7: =1-LT!F24 -> 0.998485 | I7: =1-H7 -> 0.001515 | J7: =LT!G24 -> 2.5 | K7: =LT!L24 -> 64.67 | L7: =H7^F7 -> 0.99858613 | M7: =1-L7 -> 0.001413866 | N7: =N6*L6 -> 98365.177 | O7: =N7*M7 -> 139.07518 | P7: =(((-5/24)*O6)+((2.5)*O7)+((5/24)*O8))/O7 -> 2.9095088 | Q7: =(C7*N8)+(P7*O7) -> 491535.15 | R7: =R8+Q7 -> 6463645.9 | S7: =R7/N7 -> 65.710713 | T7: =S7-K7 -> 1.040713
B8: 15 | C8: 5 | D8: ='Defunciones generales'!D25 -> 362.80834 | E8: =Homicidios!D487 -> 84.744756 | F8: =(D8-E8)/D8 -> 0.76642004 | G8: =LT!H25 -> 98208 | H8: =1-LT!F25 -> 0.994834 | I8: =1-H8 -> 0.005166 | J8: =LT!G25 -> 2.5 | K8: =LT!L25 -> 59.77 | L8: =H8^F8 -> 0.99603828 | M8: =1-L8 -> 0.0039617198 | N8: =N7*L7 -> 98226.102 | O8: =N8*M8 -> 389.1443 | P8: =(((-5/24)*O7)+((2.5)*O8)+((5/24)*O9))/O8 -> 2.7929954 | Q8: =(C8*N9)+(P8*O8) -> 490271.67 | R8: =R9+Q8 -> 5972110.8 | S8: =R8/N8 -> 60.799631 | T8: =S8-K8 -> 1.0296312 | V8: Sin COVID | W8: Con COVID
B9: 20 | C9: 5 | D9: ='Defunciones generales'!D26 -> 614.85781 | E9: =Homicidios!D488 -> 193.77018 | F9: =(D9-E9)/D9 -> 0.68485368 | G9: =LT!H26 -> 97701 | H9: =1-LT!F26 -> 0.989773 | I9: =1-H9 -> 0.010227 | J9: =LT!G26 -> 2.5 | K9: =LT!L26 -> 55.06 | L9: =H9^F9 -> 0.99298466 | M9: =1-L9 -> 0.0070153364 | N9: =N8*L8 -> 97836.958 | O9: =N9*M9 -> 686.35918 | P9: =(((-5/24)*O8)+((2.5)*O9)+((5/24)*O10))/O9 -> 2.6802947 | Q9: =(C9*N10)+(P9*O9) -> 487592.64 | R9: =R10+Q9 -> 5481839.1 | S9: =R9/N9 -> 56.030351 | T9: =S9-K9 -> 0.97035127 | V9: =([1]TV!M53-[1]TV!M71)/[1]TV!J53 -> #ERROR! | W9: =(R4-R22)/N4 -> 71.983111
B10: 25 | C10: 5 | D10: ='Defunciones generales'!D27 -> 781.20985 | E10: =Homicidios!D489 -> 218.56313 | F10: =(D10-E10)/D10 -> 0.72022482 | G10: =LT!H27 -> 96702 | H10: =1-LT!F27 -> 0.985977 | I10: =1-H10 -> 0.014023 | J10: =LT!G27 -> 2.5 | K10: =LT!L27 -> 50.61 | L10: =H10^F10 -> 0.98988036 | M10: =1-L10 -> 0.010119644 | N10: =N9*L9 -> 97150.599 | O10: =N10*M10 -> 983.12949 | P10: =(((-5/24)*O9)+((2.5)*O10)+((5/24)*O11))/O10 -> 2.5840192 | Q10: =(C10*N11)+(P10*O10) -> 483377.77 | R10: =R11+Q10 -> 4994246.5 | S10: =R10/N10 -> 51.407264 | T10: =S10-K10 -> 0.79726403 | V10: Diff | W10: =W9-V9 -> #ERROR!
B11: 30 | C11: 5 | D11: ='Defunciones generales'!D28 -> 794.23265 | E11: =Homicidios!D490 -> 193.70837 | F11: =(D11-E11)/D11 -> 0.75610627 | G11: =LT!H28 -> 95346 | H11: =1-LT!F28 -> 0.985135 | I11: =1-H11 -> 0.014865 | J11: =LT!G28 -> 2.5 | K11: =LT!L28 -> 46.29 | L11: =H11^F11 -> 0.98873998 | M11: =1-L11 -> 0.011260021 | N11: =N10*L10 -> 96167.469 | O11: =N11*M11 -> 1082.8477 | P11: =(((-5/24)*O10)+((2.5)*O11)+((5/24)*O12))/O11 -> 2.5670302 | Q11: =(C11*N12)+(P11*O11) -> 478202.81 | R11: =R12+Q11 -> 4510868.7 | S11: =R11/N11 -> 46.906389 | T11: =S11-K11 -> 0.61638887
B12: 35 | C12: 5 | D12: ='Defunciones generales'!D29 -> 901.83675 | E12: =Homicidios!D491 -> 165.32557 | F12: =(D12-E12)/D12 -> 0.81667905 | G12: =LT!H29 -> 93928 | H12: =1-LT!F29 -> 0.98288 | I12: =1-H12 -> 0.01712 | J12: =LT!G29 -> 2.5 | K12: =LT!L29 -> 41.95 | L12: =H12^F12 -> 0.98599636 | M12: =1-L12 -> 0.014003635 | N12: =N11*L11 -> 95084.621 | O12: =N12*M12 -> 1331.5303 | P12: =(((-5/24)*O11)+((2.5)*O12)+((5/24)*O13))/O12 -> 2.5987629 | Q12: =(C12*N13)+(P12*O12) -> 472225.79 | R12: =R13+Q12 -> 4032665.9 | S12: =R12/N12 -> 42.411337 | T12: =S12-K12 -> 0.46133668
B13: 40 | C13: 5 | D13: ='Defunciones generales'!D30 -> 1058.8254 | E13: =Homicidios!D492 -> 138.979 | F13: =(D13-E13)/D13 -> 0.86874229 | G13: =LT!H30 -> 92320 | H13: =1-LT!F30 -> 0.978984 | I13: =1-H13 -> 0.021016 | J13: =LT!G30 -> 2.5 | K13: =LT!L30 -> 37.64 | L13: =H13^F13 -> 0.98171713 | M13: =1-L13 -> 0.018282871 | N13: =N12*L12 -> 93753.091 | O13: =N13*M13 -> 1714.0757 | P13: =(((-5/24)*O12)+((2.5)*O13)+((5/24)*O14))/O13 -> 2.6229571 | Q13: =(C13*N14)+(P13*O13) -> 464691.02 | R13: =R14+Q13 -> 3560440.1 | S13: =R13/N13 -> 37.976776 | T13: =S13-K13 -> 0.33677564
B14: 45 | C14: 5 | D14: ='Defunciones generales'!D31 -> 1346.4424 | E14: =Homicidios!D493 -> 113.08593 | F14: =(D14-E14)/D14 -> 0.91601131 | G14: =LT!H31 -> 90380 | H14: =1-LT!F31 -> 0.97224 | I14: =1-H14 -> 0.02776 | J14: =LT!G31 -> 2.5 | K14: =LT!L31 -> 33.39 | L14: =H14^F14 -> 0.97454158 | M14: =1-L14 -> 0.025458419 | N14: =N13*L13 -> 92039.015 | O14: =N14*M14 -> 2343.1678 | P14: =(((-5/24)*O13)+((2.5)*O14)+((5/24)*O15))/O14 -> 2.6387156 | Q14: =(C14*N15)+(P14*O14) -> 454662.19 | R14: =R15+Q14 -> 3095749.1 | S14: =R14/N14 -> 33.635183 | T14: =S14-K14 -> 0.24518253
B15: 50 | C15: 5 | D15: ='Defunciones generales'!D32 -> 1748.3432 | E15: =Homicidios!D494 -> 78.604194 | F15: =(D15-E15)/D15 -> 0.95504075 | G15: =LT!H32 -> 87871 | H15: =1-LT!F32 -> 0.961811 | I15: =1-H15 -> 0.038189 | J15: =LT!G32 -> 2.5 | K15: =LT!L32 -> 29.28 | L15: =H15^F15 -> 0.96349621 | M15: =1-L15 -> 0.036503786 | N15: =N14*L14 -> 89695.848 | O15: =N15*M15 -> 3274.2381 | P15: =(((-5/24)*O14)+((2.5)*O15)+((5/24)*O16))/O15 -> 2.6472992 | Q15: =(C15*N16)+(P15*O15) -> 440775.94 | R15: =R16+Q15 -> 2641086.9 | S15: =R15/N15 -> 29.444918 | T15: =S15-K15 -> 0.16491817
B16: 55 | C16: 5 | D16: ='Defunciones generales'!D33 -> 2144.2093 | E16: =Homicidios!D495 -> 46.113221 | F16: =(D16-E16)/D16 -> 0.97849407 | G16: =LT!H33 -> 84515 | H16: =1-LT!F33 -> 0.944948 | I16: =1-H16 -> 0.055052 | J16: =LT!G33 -> 2.5 | K16: =LT!L33 -> 25.34 | L16: =H16^F16 -> 0.94609944 | M16: =1-L16 -> 0.053900559 | N16: =N15*L15 -> 86421.609 | O16: =N16*M16 -> 4658.173 | P16: =(((-5/24)*O15)+((2.5)*O16)+((5/24)*O17))/O16 -> 2.6310493 | Q16: =(C16*N17)+(P16*O16) -> 421073.07 | R16: =R17+Q16 -> 2200311 | S16: =R16/N16 -> 25.460194 | T16: =S16-K16 -> 0.12019414
B17: 60 | C17: 5 | D17: ='Defunciones generales'!D34 -> 2553.0955 | E17: =Homicidios!D496 -> 37.029433 | F17: =(D17-E17)/D17 -> 0.98549626 | G17: =LT!H34 -> 79863 | H17: =1-LT!F34 -> 0.923045 | I17: =1-H17 -> 0.076955 | J17: =LT!G34 -> 2.5 | K17: =LT!L34 -> 21.67 | L17: =H17^F17 -> 0.92411767 | M17: =1-L17 -> 0.075882334 | N17: =N16*L16 -> 81763.436 | O17: =N17*M17 -> 6204.4004 | P17: =(((-5/24)*O16)+((2.5)*O17)+((5/24)*O18))/O17 -> 2.5947149 | Q17: =(C17*N18)+(P17*O17) -> 393893.83 | R17: =R18+Q17 -> 1779237.9 | S17: =R17/N17 -> 21.760801 | T17: =S17-K17 -> 0.090801252
B18: 65 | C18: 5 | D18: ='Defunciones generales'!D35 -> 2678.3862 | E18: =Homicidios!D497 -> 22.303634 | F18: =(D18-E18)/D18 -> 0.99167273 | G18: =LT!H35 -> 73717 | H18: =1-LT!F35 -> 0.900231 | I18: =1-H18 -> 0.099769 | J18: =LT!G35 -> 2.5 | K18: =LT!L35 -> 18.27 | L18: =H18^F18 -> 0.90101925 | M18: =1-L18 -> 0.098980748 | N18: =N17*L17 -> 75559.036 | O18: =N18*M18 -> 7478.8899 | P18: =(((-5/24)*O17)+((2.5)*O18)+((5/24)*O19))/O18 -> 2.5954092 | Q18: =(C18*N19)+(P18*O18) -> 359811.51 | R18: =R19+Q18 -> 1385344.1 | S18: =R18/N18 -> 18.334591 | T18: =S18-K18 -> 0.064591495
B19: 70 | C19: 5 | D19: ='Defunciones generales'!D36 -> 2880.285 | E19: =Homicidios!D498 -> 18.260291 | F19: =(D19-E19)/D19 -> 0.99366025 | G19: =LT!H36 -> 66362 | H19: =1-LT!F36 -> 0.857722 | I19: =1-H19 -> 0.142278 | J19: =LT!G36 -> 2.5 | K19: =LT!L36 -> 15.02 | L19: =H19^F19 -> 0.85855697 | M19: =1-L19 -> 0.14144303 | N19: =N18*L18 -> 68080.146 | O19: =N19*M19 -> 9629.4625 | P19: =(((-5/24)*O18)+((2.5)*O19)+((5/24)*O20))/O19 -> 2.6024867 | Q19: =(C19*N20)+(P19*O19) -> 317313.97 | R19: =R20+Q19 -> 1025532.5 | S19: =R19/N19 -> 15.063607 | T19: =S19-K19 -> 0.043606755
B20: 75 | C20: 5 | D20: ='Defunciones generales'!D37 -> 3149.8899 | E20: =Homicidios!D499 -> 6.5910369 | F20: =(D20-E20)/D20 -> 0.99790753 | G20: =LT!H37 -> 56920 | H20: =1-LT!F37 -> 0.790615 | I20: =1-H20 -> 0.209385 | J20: =LT!G37 -> 2.5 | K20: =LT!L37 -> 12.09 | L20: =H20^F20 -> 0.79100377 | M20: =1-L20 -> 0.20899623 | N20: =N19*L19 -> 58450.684 | O20: =N20*M20 -> 12215.972 | P20: =(((-5/24)*O19)+((2.5)*O20)+((5/24)*O21))/O20 -> 2.5831667 | Q20: =(C20*N21)+(P20*O20) -> 262729.45 | R20: =R21+Q20 -> 708218.58 | S20: =R20/N20 -> 12.116515 | T20: =S20-K20 -> 0.026514952
B21: 80 | C21: 5 | D21: ='Defunciones generales'!D38 -> 3125.3408 | E21: =Homicidios!D500 -> 2.5305237 | F21: =(D21-E21)/D21 -> 0.99919032 | G21: =LT!H38 -> 45002 | H21: =1-LT!F38 -> 0.686042 | I21: =1-H21 -> 0.313958 | J21: =LT!G38 -> 2.5 | K21: =LT!L38 -> 9.63 | L21: =H21^F21 -> 0.68625134 | M21: =1-L21 -> 0.31374866 | N21: =N20*L20 -> 46234.711 | O21: =N21*M21 -> 14506.079 | P21: =C21+(F21*(I21/M21)*(J21-C21)) -> 2.5003575 | Q21: =(C21*N22)+(P21*O21) -> 194913.55 | R21: =R22+Q21 -> 445489.13 | S21: =R21/N21 -> 9.6353826 | T21: =S21-K21 -> 0.0053826293
B22: 85 | C22: 5 | D22: ='Defunciones generales'!D39 -> 4561.6983 | E22: =Homicidios!D501 -> 3.5516613 | F22: =(D22-E22)/D22 -> 0.99922142 | G22: =LT!H39 -> 30873 | H22: =1-LT!F39 -> 0 | I22: =1-H22 -> 1 | J22: =LT!G39 -> NA | K22: =LT!L39 -> 7.9 | L22: =H22^F22 -> 0 | M22: =1-L22 -> 1 | N22: =N21*L21 -> 31728.633 | O22: =N22*M22 -> 31728.633 | P22: =K22/F22 -> 7.9061556 | Q22: =N22/LT!E39 -> 250575.59 | R22: =Q22 -> 250575.59 | S22: =R22/N22 -> 7.8974594 | T22: =S22-K22 -> -0.0025406127
B24: Mujeres, 2019
B26: Age x | C26: n | D26: nDx | E26: nDxi | I26: nqx | K26: e0 | M26: nqx_i | O26: ndx_i | Q26: L | R26: T | S26: e0_i | T26: diff | AA26: Hombres | AB26: Mujeres
B27: 0 | C27: 1 | D27: ='Defunciones generales'!D78 -> 611.38892 | E27: =Homicidios!D1056 -> 0.50779134 | F27: =(D27-E27)/D27 -> 0.99916945 | G27: =LT!H78 -> 100000 | H27: =1-LT!F78 -> 0.988955 | I27: =1-H27 -> 0.011045 | J27: =LT!G78 -> 0.08 | K27: =LT!L78 -> 79.11 | L27: =H27^F27 -> 0.98896412 | M27: =1-L27 -> 0.011035877 | N27: 100000 | O27: =N27*M27 -> 1103.5877 | P27: =C27+(F27*(I27/M27)*(J27-C27)) -> 0.080004235 | Q27: =(C27*N28)+(P27*O27) -> 98984.704 | R27: =R28+Q27 -> 7928350.1 | S27: =R27/N27 -> 79.283501 | T27: =S27-K27 -> 0.17350066 | Z27: Sin homicidios | AA27: =S4 -> 74.488867 | AB27: =S27 -> 79.283501
B28: 1 | C28: 4 | D28: ='Defunciones generales'!D79 -> 121.53064 | E28: =Homicidios!D1057 -> 0.50779134 | F28: =(D28-E28)/D28 -> 0.9958217 | G28: =LT!H79 -> 98895 | H28: =1-LT!F79 -> 0.998026 | I28: =1-H28 -> 0.001974 | J28: =LT!G79 -> 1.51 | K28: =LT!L79 -> 78.99 | L28: =H28^F28 -> 0.99803424 | M28: =1-L28 -> 0.0019657601 | N28: =N27*L27 -> 98896.412 | O28: =N28*M28 -> 194.40663 | P28: =C28+(F28*(I28/M28)*(J28-C28)) -> 1.5100103 | Q28: =(C28*N29)+(P28*O28) -> 395101.58 | R28: =R29+Q28 -> 7829365.4 | S28: =R28/N28 -> 79.167335 | T28: =S28-K28 -> 0.17733462 | V28: Número de años que se espera que viva una mujer de 0 años hasta llegar a los 85 años. | Z28: Con homicidios | AA28: =K4 -> 73.46 | AB28: =K27 -> 79.11
B29: 5 | C29: 5 | D29: ='Defunciones generales'!D80 -> 78.51978 | E29: =Homicidios!D1058 -> 1.523374 | F29: =(D29-E29)/D29 -> 0.98059885 | G29: =LT!H80 -> 98700 | H29: =1-LT!F80 -> 0.998837 | I29: =1-H29 -> 0.001163 | J29: =LT!G80 -> 2.5 | K29: =LT!L80 -> 75.15 | L29: =H29^F29 -> 0.99885955 | M29: =1-L29 -> 0.0011404493 | N29: =N28*L28 -> 98702.006 | O29: =N29*M29 -> 112.56464 | P29: =C29+(F29*(I29/M29)*(J29-C29)) -> 2.5000282 | Q29: =(C29*N30)+(P29*O29) -> 493228.62 | R29: =R30+Q29 -> 7434263.8 | S29: =R29/N29 -> 75.320291 | T29: =S29-K29 -> 0.17029097 | AA29: =AA27-AA28 -> 1.0288673 | AB29: =AB27-AB28 -> 0.17350066
B30: 10 | C30: 5 | D30: ='Defunciones generales'!D81 -> 80.020338 | E30: =Homicidios!D1059 -> 2.5077913 | F30: =(D30-E30)/D30 -> 0.96866058 | G30: =LT!H81 -> 98585 | H30: =1-LT!F81 -> 0.998824 | I30: =1-H30 -> 0.001176 | J30: =LT!G81 -> 2.5 | K30: =LT!L81 -> 70.23 | L30: =H30^F30 -> 0.99886083 | M30: =1-L30 -> 0.0011391658 | N30: =N29*L29 -> 98589.441 | O30: =N30*M30 -> 112.30972 | P30: =(((-5/24)*O29)+((2.5)*O30)+((5/24)*O31))/O30 -> 2.6223774 | Q30: =(C30*N31)+(P30*O30) -> 492680.17 | R30: =R31+Q30 -> 6941035.2 | S30: =R30/N30 -> 70.403434 | T30: =S30-K30 -> 0.17343361
B31: 15 | C31: 5 | D31: ='Defunciones generales'!D82 -> 137.03462 | E31: =Homicidios!D1060 -> 11.570122 | F31: =(D31-E31)/D31 -> 0.91556789 | G31: =LT!H82 -> 98470 | H31: =1-LT!F82 -> 0.99802 | I31: =1-H31 -> 0.00198 | J31: =LT!G82 -> 2.5 | K31: =LT!L82 -> 65.31 | L31: =H31^F31 -> 0.99818702 | M31: =1-L31 -> 0.0018129761 | N31: =N30*L30 -> 98477.131 | O31: =N31*M31 -> 178.53668 | P31: =(((-5/24)*O30)+((2.5)*O31)+((5/24)*O32))/O31 -> 2.6569282 | Q31: =(C31*N32)+(P31*O31) -> 491967.33 | R31: =R32+Q31 -> 6448355 | S31: =R31/N31 -> 65.480736 | T31: =S31-K31 -> 0.17073553 | V31: Sin COVID | W31: Con COVID
B32: 20 | C32: 5 | D32: ='Defunciones generales'!D83 -> 178.04554 | E32: =Homicidios!D1061 -> 21.17141 | F32: =(D32-E32)/D32 -> 0.88108992 | G32: =LT!H83 -> 98275 | H32: =1-LT!F83 -> 0.997151 | I32: =1-H32 -> 0.002849 | J32: =LT!G83 -> 2.5 | K32: =LT!L83 -> 60.43 | L32: =H32^F32 -> 0.99748935 | M32: =1-L32 -> 0.0025106508 | N32: =N31*L31 -> 98298.595 | O32: =N32*M32 -> 246.79345 | P32: =(((-5/24)*O31)+((2.5)*O32)+((5/24)*O33))/O32 -> 2.6112085 | Q32: =(C32*N33)+(P32*O32) -> 490903.43 | R32: =R33+Q32 -> 5956387.7 | S32: =R32/N32 -> 60.59484 | T32: =S32-K32 -> 0.16484046 | V32: =([1]TV!M29-[1]TV!M47)/[1]TV!J29 -> #ERROR! | W32: =(R27-R45)/N27 -> 75.851891 | AH32: =LN(M22) -> 0
B33: 25 | C33: 5 | D33: ='Defunciones generales'!D84 -> 225.55644 | E33: =Homicidios!D1062 -> 26.67141 | F33: =(D33-E33)/D33 -> 0.88175284 | G33: =LT!H84 -> 97995 | H33: =1-LT!F84 -> 0.996412 | I33: =1-H33 -> 0.003588 | J33: =LT!G84 -> 2.5 | K33: =LT!L84 -> 55.6 | L33: =H33^F33 -> 0.9968356 | M33: =1-L33 -> 0.0031644012 | N33: =N32*L32 -> 98051.801 | O33: =N33*M33 -> 310.27524 | P33: =(((-5/24)*O32)+((2.5)*O33)+((5/24)*O34))/O33 -> 2.6325239 | Q33: =(C33*N34)+(P33*O33) -> 489524.44 | R33: =R34+Q33 -> 5465484.2 | S33: =R33/N33 -> 55.740784 | T33: =S33-K33 -> 0.14078352 | V33: Diff | W33: =W32-V32 -> #ERROR!
B34: 30 | C34: 5 | D34: ='Defunciones generales'!D85 -> 299.57618 | E34: =Homicidios!D1063 -> 20.140244 | F34: =(D34-E34)/D34 -> 0.93277088 | G34: =LT!H85 -> 97643 | H34: =1-LT!F85 -> 0.995129 | I34: =1-H34 -> 0.004871 | J34: =LT!G85 -> 2.5 | K34: =LT!L85 -> 50.79 | L34: =H34^F34 -> 0.99545573 | M34: =1-L34 -> 0.0045442722 | N34: =N33*L33 -> 97741.526 | O34: =N34*M34 -> 444.1641 | P34: =(((-5/24)*O33)+((2.5)*O34)+((5/24)*O35))/O34 -> 2.631416 | Q34: =(C34*N35)+(P34*O34) -> 487655.59 | R34: =R35+Q34 -> 4975959.8 | S34: =R34/N34 -> 50.909373 | T34: =S34-K34 -> 0.11937285
B35: 35 | C35: 5 | D35: ='Defunciones generales'!D86 -> 383.75069 | E35: =Homicidios!D1064 -> 17.177414 | F35: =(D35-E35)/D35 -> 0.95523809 | G35: =LT!H86 -> 97167 | H35: =1-LT!F86 -> 0.993648 | I35: =1-H35 -> 0.006352 | J35: =LT!G86 -> 2.5 | K35: =LT!L86 -> 46.03 | L35: =H35^F35 -> 0.99393146 | M35: =1-L35 -> 0.0060685369 | N35: =N34*L34 -> 97297.362 | O35: =N35*M35 -> 590.45263 | P35: =(((-5/24)*O34)+((2.5)*O35)+((5/24)*O36))/O35 -> 2.6523363 | Q35: =(C35*N36)+(P35*O35) -> 485100.62 | R35: =R36+Q35 -> 4488304.2 | S35: =R35/N35 -> 46.129763 | T35: =S35-K35 -> 0.099762534
B36: 40 | C36: 5 | D36: ='Defunciones generales'!D87 -> 545.13898 | E36: =Homicidios!D1065 -> 18.101287 | F36: =(D36-E36)/D36 -> 0.9667951 | G36: =LT!H87 -> 96550 | H36: =1-LT!F87 -> 0.990633 | I36: =1-H36 -> 0.009367 | J36: =LT!G87 -> 2.5 | K36: =LT!L87 -> 41.31 | L36: =H36^F36 -> 0.99094262 | M36: =1-L36 -> 0.0090573826 | N36: =N35*L35 -> 96706.909 | O36: =N36*M36 -> 875.91147 | P36: =(((-5/24)*O35)+((2.5)*O36)+((5/24)*O37))/O36 -> 2.6975219 | Q36: =(C36*N37)+(P36*O36) -> 481517.78 | R36: =R37+Q36 -> 4003203.6 | S36: =R36/N36 -> 41.395218 | T36: =S36-K36 -> 0.085217824
B37: 45 | C37: 5 | D37: ='Defunciones generales'!D88 -> 822.70702 | E37: =Homicidios!D1066 -> 8.5623308 | F37: =(D37-E37)/D37 -> 0.98959249 | G37: =LT!H88 -> 95646 | H37: =1-LT!F88 -> 0.985018 | I37: =1-H37 -> 0.014982 | J37: =LT!G88 -> 2.5 | K37: =LT!L88 -> 36.67 | L37: =H37^F37 -> 0.98517276 | M37: =1-L37 -> 0.014827236 | N37: =N36*L36 -> 95830.998 | O37: =N37*M37 -> 1420.9089 | P37: =(((-5/24)*O36)+((2.5)*O37)+((5/24)*O38))/O37 -> 2.6598903 | Q37: =(C37*N38)+(P37*O37) -> 475829.91 | R37: =R38+Q37 -> 3521685.8 | S37: =R37/N37 -> 36.748921 | T37: =S37-K37 -> 0.078921288
B38: 50 | C38: 5 | D38: ='Defunciones generales'!D89 -> 1087.2756 | E38: =Homicidios!D1067 -> 7.5701221 | F38: =(D38-E38)/D38 -> 0.99303753 | G38: =LT!H89 -> 94213 | H38: =1-LT!F89 -> 0.979027 | I38: =1-H38 -> 0.020973 | J38: =LT!G89 -> 2.5 | K38: =LT!L89 -> 32.19 | L38: =H38^F38 -> 0.97917149 | M38: =1-L38 -> 0.020828508 | N38: =N37*L37 -> 94410.089 | O38: =N38*M38 -> 1966.4213 | P38: =(((-5/24)*O37)+((2.5)*O38)+((5/24)*O39))/O38 -> 2.691853 | Q38: =(C38*N39)+(P38*O38) -> 467511.66 | R38: =R39+Q38 -> 3045855.9 | S38: =R38/N38 -> 32.261975 | T38: =S38-K38 -> 0.071974573
B39: 55 | C39: 5 | D39: ='Defunciones generales'!D90 -> 1517.8834 | E39: =Homicidios!D1068 -> 9.0779134 | F39: =(D39-E39)/D39 -> 0.99401936 | G39: =LT!H90 -> 92237 | H39: =1-LT!F90 -> 0.964834 | I39: =1-H39 -> 0.035166 | J39: =LT!G90 -> 2.5 | K39: =LT!L90 -> 27.83 | L39: =H39^F39 -> 0.9650406 | M39: =1-L39 -> 0.034959405 | N39: =N38*L38 -> 92443.668 | O39: =N39*M39 -> 3231.7756 | P39: =(((-5/24)*O38)+((2.5)*O39)+((5/24)*O40))/O39 -> 2.6726523 | Q39: =(C39*N40)+(P39*O39) -> 454696.87 | R39: =R40+Q39 -> 2578344.2 | S39: =R39/N39 -> 27.890977 | T39: =S39-K39 -> 0.060977261
B40: 60 | C40: 5 | D40: ='Defunciones generales'!D91 -> 1931.9849 | E40: =Homicidios!D1069 -> 1.5 | F40: =(D40-E40)/D40 -> 0.9992236 | G40: =LT!H91 -> 88993 | H40: =1-LT!F91 -> 0.947897 | I40: =1-H40 -> 0.052103 | J40: =LT!G91 -> 2.5 | K40: =LT!L91 -> 23.75 | L40: =H40^F40 -> 0.94793638 | M40: =1-L40 -> 0.052063619 | N40: =N39*L39 -> 89211.892 | O40: =N40*M40 -> 4644.6939 | P40: =(((-5/24)*O39)+((2.5)*O40)+((5/24)*O41))/O40 -> 2.6383993 | Q40: =(C40*N41)+(P40*O40) -> 435090.55 | R40: =R41+Q40 -> 2123647.4 | S40: =R40/N40 -> 23.804532 | T40: =S40-K40 -> 0.05453223
B41: 65 | C41: 5 | D41: ='Defunciones generales'!D92 -> 2251.0666 | E41: =Homicidios!D1070 -> 5.5389567 | F41: =(D41-E41)/D41 -> 0.99753941 | G41: =LT!H92 -> 84356 | H41: =1-LT!F92 -> 0.925121 | I41: =1-H41 -> 0.074879 | J41: =LT!G92 -> 2.5 | K41: =LT!L92 -> 19.92 | L41: =H41^F41 -> 0.92529819 | M41: =1-L41 -> 0.074701813 | N41: =N40*L40 -> 84567.198 | O41: =N41*M41 -> 6317.323 | P41: =(((-5/24)*O40)+((2.5)*O41)+((5/24)*O42))/O41 -> 2.6379444 | Q41: =(C41*N42)+(P41*O41) -> 407914.12 | R41: =R42+Q41 -> 1688556.8 | S41: =R41/N41 -> 19.967042 | T41: =S41-K41 -> 0.047042183
B42: 70 | C42: 5 | D42: ='Defunciones generales'!D93 -> 2540.1418 | E42: =Homicidios!D1071 -> 2.0077913 | F42: =(D42-E42)/D42 -> 0.99920958 | G42: =LT!H93 -> 78040 | H42: =1-LT!F93 -> 0.887103 | I42: =1-H42 -> 0.112897 | J42: =LT!G93 -> 2.5 | K42: =LT!L93 -> 16.33 | L42: =H42^F42 -> 0.887187 | M42: =1-L42 -> 0.112813 | N42: =N41*L41 -> 78249.875 | O42: =N42*M42 -> 8827.603 | P42: =(((-5/24)*O41)+((2.5)*O42)+((5/24)*O43))/O42 -> 2.634036 | Q42: =(C42*N43)+(P42*O42) -> 370363.58 | R42: =R43+Q42 -> 1280642.7 | S42: =R42/N42 -> 16.366067 | T42: =S42-K42 -> 0.036066895
B43: 75 | C43: 5 | D43: ='Defunciones generales'!D94 -> 2842.2183 | E43: =Homicidios!D1072 -> 2.523374 | F43: =(D43-E43)/D43 -> 0.99911218 | G43: =LT!H94 -> 69229 | H43: =1-LT!F94 -> 0.827052 | I43: =1-H43 -> 0.172948 | J43: =LT!G94 -> 2.5 | K43: =LT!L94 -> 13.09 | L43: =H43^F43 -> 0.82719144 | M43: =1-L43 -> 0.17280856 | N43: =N42*L42 -> 69422.272 | O43: =N43*M43 -> 11996.763 | P43: =(((-5/24)*O42)+((2.5)*O43)+((5/24)*O44))/O43 -> 2.6141342 | Q43: =(C43*N44)+(P43*O43) -> 318488.69 | R43: =R44+Q43 -> 910279.1 | S43: =R43/N43 -> 13.112206 | T43: =S43-K43 -> 0.022205607
...

Sheet LT
A1: lt_desc | B1: year | C1: sex | D1: age | E1: mx | F1: qx | G1: ax | H1: lx | I1: dx | J1: Lx | K1: Tx | L1: ex
A2: LT VR/Census, MEX | B2: 2010 | C2: m | D2: 0 | E2: 0.016491 | F2: 0.016247 | G2: 0.09 | H2: 100000 | I2: 1625 | J2: 98520 | K2: 7265016 | L2: 72.65
A3: LT VR/Census, MEX | B3: 2010 | C3: m | D3: 1 | E3: 0.000764 | F3: 0.003049 | G3: 1.6 | H3: 98375 | I3: 300 | J3: 392783 | K3: 7166496 | L3: 72.85
A4: LT VR/Census, MEX | B4: 2010 | C4: m | D4: 5 | E4: 0.000299 | F4: 0.001492 | G4: 2.5 | H4: 98075 | I4: 146 | J4: 490011 | K4: 6773713 | L4: 69.07
A5: LT VR/Census, MEX | B5: 2010 | C5: m | D5: 10 | E5: 0.000395 | F5: 0.001974 | G5: 2.5 | H5: 97929 | I5: 193 | J5: 489162 | K5: 6283702 | L5: 64.17
A6: LT VR/Census, MEX | B6: 2010 | C6: m | D6: 15 | E6: 0.00111 | F6: 0.005535 | G6: 2.5 | H6: 97736 | I6: 541 | J6: 487326 | K6: 5794541 | L6: 59.29
A7: LT VR/Census, MEX | B7: 2010 | C7: m | D7: 20 | E7: 0.001882 | F7: 0.009366 | G7: 2.5 | H7: 97195 | I7: 910 | J7: 483698 | K7: 5307215 | L7: 54.6
A8: LT VR/Census, MEX | B8: 2010 | C8: m | D8: 25 | E8: 0.002478 | F8: 0.012312 | G8: 2.5 | H8: 96284 | I8: 1185 | J8: 478459 | K8: 4823517 | L8: 50.1
A9: LT VR/Census, MEX | B9: 2010 | C9: m | D9: 30 | E9: 0.002989 | F9: 0.014833 | G9: 2.5 | H9: 95099 | I9: 1411 | J9: 471968 | K9: 4345058 | L9: 45.69
A10: LT VR/Census, MEX | B10: 2010 | C10: m | D10: 35 | E10: 0.003492 | F10: 0.01731 | G10: 2.5 | H10: 93688 | I10: 1622 | J10: 464387 | K10: 3873090 | L10: 41.34
A11: LT VR/Census, MEX | B11: 2010 | C11: m | D11: 40 | E11: 0.004316 | F11: 0.021352 | G11: 2.5 | H11: 92067 | I11: 1966 | J11: 455419 | K11: 3408702 | L11: 37.02
A12: LT VR/Census, MEX | B12: 2010 | C12: m | D12: 45 | E12: 0.005935 | F12: 0.029239 | G12: 2.5 | H12: 90101 | I12: 2634 | J12: 443918 | K12: 2953284 | L12: 32.78
A13: LT VR/Census, MEX | B13: 2010 | C13: m | D13: 50 | E13: 0.008167 | F13: 0.040016 | G13: 2.5 | H13: 87466 | I13: 3500 | J13: 428582 | K13: 2509366 | L13: 28.69
... A19: LT VR/Census, MEX | B19: 2010 | C19: m | D19: 80 | E19: 0.078491 | F19: 0.328076 | G19: 2.5 | H19: 42820 | I19: 14048 | J19: 178981 | K19: 395443 | L19: 9.23
A20: LT VR/Census, MEX | B20: 2010 | C20: m | D20: 85 | E20: 0.13292 | F20: 1 | G20: NA | H20: 28772 | I20: 28772 | J20: 216462 | K20: 216462 | L20: 7.52
A21: LT VR/Census, MEX | B21: 2019 | C21: m | D21: 0 | E21: 0.012994 | F21: 0.01284 | G21: 0.08 | H21: 100000 | I21: 1284 | J21: 98819 | K21: 7346263 | L21: 73.46
A22: LT VR/Census, MEX | B22: 2019 | C22: m | D22: 1 | E22: 0.000609 | F22: 0.002431 | G22: 1.61 | H22: 98716 | I22: 240 | J22: 394291 | K22: 7247445 | L22: 73.42
A23: LT VR/Census, MEX | B23: 2019 | C23: m | D23: 5 | E23: 0.000241 | F23: 0.001205 | G23: 2.5 | H23: 98476 | I23: 119 | J23: 492083 | K23: 6853153 | L23: 69.59
A24: LT VR/Census, MEX | B24: 2019 | C24: m | D24: 10 | E24: 0.000303 | F24: 0.001515 | G24: 2.5 | H24: 98357 | I24: 149 | J24: 491414 | K24: 6361070 | L24: 64.67
A25: LT VR/Census, MEX | B25: 2019 | C25: m | D25: 15 | E25: 0.001036 | F25: 0.005166 | G25: 2.5 | H25: 98208 | I25: 507 | J25: 489773 | K25: 5869657 | L25: 59.77
A26: LT VR/Census, MEX | B26: 2019 | C26: m | D26: 20 | E26: 0.002056 | F26: 0.010227 | G26: 2.5 | H26: 97701 | I26: 999 | J26: 486006 | K26: 5379884 | L26: 55.06
A27: LT VR/Census, MEX | B27: 2019 | C27: m | D27: 25 | E27: 0.002824 | F27: 0.014023 | G27: 2.5 | H27: 96702 | I27: 1356 | J27: 480118 | K27: 4893878 | L27: 50.61
A28: LT VR/Census, MEX | B28: 2019 | C28: m | D28: 30 | E28: 0.002995 | F28: 0.014865 | G28: 2.5 | H28: 95346 | I28: 1417 | J28: 473184 | K28: 4413760 | L28: 46.29
A29: LT VR/Census, MEX | B29: 2019 | C29: m | D29: 35 | E29: 0.003454 | F29: 0.01712 | G29: 2.5 | H29: 93928 | I29: 1608 | J29: 465621 | K29: 3940575 | L29: 41.95
A30: LT VR/Census, MEX | B30: 2019 | C30: m | D30: 40 | E30: 0.004248 | F30: 0.021016 | G30: 2.5 | H30: 92320 | I30: 1940 | J30: 456750 | K30: 3474954 | L30: 37.64
A31: LT VR/Census, MEX | B31: 2019 | C31: m | D31: 45 | E31: 0.00563 | F31: 0.02776 | G31: 2.5 | H31: 90380 | I31: 2509 | J31: 445627 | K31: 3018204 | L31: 33.39
A32: LT VR/Census, MEX | B32: 2019 | C32: m | D32: 50 | E32: 0.007787 | F32: 0.038189 | G32: 2.5 | H32: 87871 | I32: 3356 | J32: 430966 | K32: 2572576 | L32: 29.28
... A38: LT VR/Census, MEX | B38: 2019 | C38: m | D38: 80 | E38: 0.074484 | F38: 0.313958 | G38: 2.5 | H38: 45002 | I38: 14129 | J38: 189688 | K38: 433509 | L38: 9.63
A39: LT VR/Census, MEX | B39: 2019 | C39: m | D39: 85 | E39: 0.126623 | F39: 1 | G39: NA | H39: 30873 | I39: 30873 | J39: 243821 | K39: 243821 | L39: 7.9
A40: LT VR/Census, MEX | B40: 2021 | C40: m | D40: 0 | E40: 0.011246 | F40: 0.011131 | G40: 0.08 | H40: 100000 | I40: 1113 | J40: 98971 | K40: 6907097 | L40: 69.07
A41: LT VR/Census, MEX | B41: 2021 | C41: m | D41: 1 | E41: 0.000474 | F41: 0.001894 | G41: 1.62 | H41: 98887 | I41: 187 | J41: 395102 | K41: 6808126 | L41: 68.85
A42: LT VR/Census, MEX | B42: 2021 | C42: m | D42: 5 | E42: 0.00018 | F42: 0.000901 | G42: 2.5 | H42: 98700 | I42: 89 | J42: 493276 | K42: 6413024 | L42: 64.98
A43: LT VR/Census, MEX | B43: 2021 | C43: m | D43: 10 | E43: 0.000329 | F43: 0.001644 | G43: 2.5 | H43: 98611 | I43: 162 | J43: 492648 | K43: 5919748 | L43: 60.03
A44: LT VR/Census, MEX | B44: 2021 | C44: m | D44: 15 | E44: 0.000965 | F44: 0.004814 | G44: 2.5 | H44: 98449 | I44: 474 | J44: 491058 | K44: 5427100 | L44: 55.13
A45: LT VR/Census, MEX | B45: 2021 | C45: m | D45: 20 | E45: 0.001922 | F45: 0.009562 | G45: 2.5 | H45: 97975 | I45: 937 | J45: 487531 | K45: 4936042 | L45: 50.38
A46: LT VR/Census, MEX | B46: 2021 | C46: m | D46: 25 | E46: 0.002985 | F46: 0.014814 | G46: 2.5 | H46: 97038 | I46: 1438 | J46: 481595 | K46: 4448511 | L46: 45.84
A47: LT VR/Census, MEX | B47: 2021 | C47: m | D47: 30 | E47: 0.003582 | F47: 0.017753 | G47: 2.5 | H47: 95600 | I47: 1697 | J47: 473758 | K47: 3966916 | L47: 41.49
A48: LT VR/Census, MEX | B48: 2021 | C48: m | D48: 35 | E48: 0.00448 | F48: 0.022154 | G48: 2.5 | H48: 93903 | I48: 2080 | J48: 464314 | K48: 3493157 | L48: 37.2
A49: LT VR/Census, MEX | B49: 2021 | C49: m | D49: 40 | E49: 0.006002 | F49: 0.029565 | G49: 2.5 | H49: 91823 | I49: 2715 | J49: 452327 | K49: 3028843 | L49: 32.99
A50: LT VR/Census, MEX | B50: 2021 | C50: m | D50: 45 | E50: 0.008562 | F50: 0.041911 | G50: 2.5 | H50: 89108 | I50: 3735 | J50: 436204 | K50: 2576516 | L50: 28.91
...

Sheet Homicidios
A1: year | B1: sex | C1: age | D1: deaths
A2: 1990 | B2: male | C2: 0 | D2: 2.0313874
A3: 1990 | B3: male | C3: 1 | D3: 1.0156937
A4: 1990 | B4: male | C4: 5 | D4: 10.156937
A5: 1990 | B5: male | C5: 10 | D5: 6.0941621
A6: 1990 | B6: male | C6: 15 | D6: 49.768991
A7: 1990 | B7: male | C7: 20 | D7: 97.506594
A8: 1990 | B8: male | C8: 25 | D8: 108.67922
A9: 1990 | B9: male | C9: 30 | D9: 81.172823
A10: 1990 | B10: male | C10: 35 | D10: 88.365351
A11: 1990 | B11: male | C11: 40 | D11: 65.004396
A12: 1990 | B12: male | C12: 45 | D12: 50.784685
A13: 1990 | B13: male | C13: 50 | D13: 40.627748
... A538: 2021 | B538: male | C538: 85 | D538: 2.0048077
A539: 2023 | B539: male | C539: 1 | D539: NA
A540: 2023 | B540: male | C540: 5 | D540: NA
A541: 2023 | B541: male | C541: 10 | D541: NA
A542: 2023 | B542: male | C542: 15 | D542: NA
A543: 2023 | B543: male | C543: 20 | D543: NA
A544: 2023 | B544: male | C544: 25 | D544: NA
A545: 2023 | B545: male | C545: 30 | D545: NA
A546: 2023 | B546: male | C546: 35 | D546: NA
A547: 2023 | B547: male | C547: 40 | D547: NA
A548: 2023 | B548: male | C548: 45 | D548: NA
A549: 2023 | B549: male | C549: 50 | D549: NA
A550: 2023 | B550: male | C550: 55 | D550: NA
... A556: 2023 | B556: male | C556: 85 | D556: NA
A557: 2024 | B557: male | C557: 1 | D557: 1.0014409
A558: 2024 | B558: male | C558: 5 | D558: 1.0014409
A559: 2024 | B559: male | C559: 10 | D559: 4.0057637
A560: 2024 | B560: male | C560: 15 | D560: 32.04611
A561: 2024 | B561: male | C561: 20 | D561: 86.123919
A562: 2024 | B562: male | C562: 25 | D562: 114.16427
A563: 2024 | B563: male | C563: 30 | D563: 92.132565
A564: 2024 | B564: male | C564: 35 | D564: 94.135447
A565: 2024 | B565: male | C565: 40 | D565: 76.10951
A566: 2024 | B566: male | C566: 45 | D566: 68.097983
A567: 2024 | B567: male | C567: 50 | D567: 42.060519
A568: 2024 | B568: male | C568: 55 | D568: 30.043228
... A1111: 2021 | B1111: female | C1111: 85 | D1111: 0
...

Sheet Defunciones generales
A1: year | B1: sex | C1: age | D1: deaths
A2: 2010 | B2: male | C2: 0 | D2: 1068.5511
A3: 2010 | B3: male | C3: 1 | D3: 210.93574
A4: 2010 | B4: male | C4: 5 | D4: 111.5328
A5: 2010 | B5: male | C5: 10 | D5: 150.17154
A6: 2010 | B6: male | C6: 15 | D6: 429.06867
A7: 2010 | B7: male | C7: 20 | D7: 585.91325
A8: 2010 | B8: male | C8: 25 | D8: 651.12723
A9: 2010 | B9: male | C9: 30 | D9: 747.83626
A10: 2010 | B10: male | C10: 35 | D10: 889.28826
A11: 2010 | B11: male | C11: 40 | D11: 1000.2653
A12: 2010 | B12: male | C12: 45 | D12: 1211.1798
A13: 2010 | B13: male | C13: 50 | D13: 1430.6451
... A115: 2021 | B115: female | C115: 85 | D115: 7433.5375
